<?xml version="1.0"?>




<robot name="simple_box">
    <material name = "blue">
    <color rgba= "0 0 1 "/>     
    </material>
    <material name = "red">
        <color rgba = "1.0 0.0 0.0"/>
    </material>
    <material name = "green">
        <color rgba = "0.0 1.0 0.0"/>
    </material>
    <material name = "white">
        <color rgba = "0.0 0.0 0.0"/>
    </material>



<link name="dummy"/>
<joint name="dummy_joint" type="fixed">
<parent link="dummy"/>
<child link="base_link"/>
</joint>



<link name="base_link">
    <inertial>
      <origin xyz="2 0 0" />
      <mass value="1.0" />
      <inertia  ixx="1.0" ixy="0.0"  ixz="0.0"  iyy="100.0"  iyz="0.0"  izz="1.0" />
    </inertial>
  
    <visual>
      <origin xyz="0 0 0.5"/>
      <geometry>
        <box size="1 1 1" />
        <material name ="blue"/> 
      </geometry>
    </visual>
    
    <collision>
      <origin xyz="0 0 0.5"/>
      <geometry>
        <box size="1 1 1" />
      </geometry>
    </collision>
  </link>

   <joint name="joint_0" type="revolute">
    <axis xyz="0 0 -1"/>
   <limit effort="30" velocity="1.0" lower="0" upper="180" />
            <parent link="base_link"/>
            <child link="top"/>
            <origin xyz ="0.0 0.0 0.5"/>
    </joint>


<link name="top">
    <inertial>
      <origin xyz="0 0 1" />
      <mass value="1.0" />
      <inertia  ixx="1.0" ixy="0.0"  ixz="0.0"  iyy="100.0"  iyz="0.0"  izz="1.0" />
    </inertial>
  
    <visual>
      <origin xyz="0 0 1"/>
      <geometry>
        <box size="2 0.2 1" />
        <material name ="red"/> 
      </geometry>
    </visual>
    
    <collision>
      <origin xyz="0 0 1"/>
      <geometry>
        <box size="2 0.2 1" />
      </geometry>
    </collision>
  </link>
  
</robot>